Workbook

Sheet Summary
A1: OpHUB review v3 — 27 Oct 2026
A2: Everything since v2 (24 Oct evening): fix round 2, three database security batches, 15 server functions redeployed, and the new features you asked for. Every v2 row is carried forward with its status now.
A4: At a glance
B5: v2 (24 Oct) | C5: Now (27 Oct) | D5: Notes
A6: Bugs (137 from the 23 Oct review)
A7: Fixed | B7: 52 | C7: =COUNTIF('Bugs Now'!$G$5:$G$141,"Fixed") -> 128 | D7: Fix round 2 (25 Oct) fixed almost all the rest.
A8: Partly fixed | B8: 8 | C8: =COUNTIF('Bugs Now'!$G$5:$G$141,"Partly fixed") -> 4 | D8: CORE-M3, CORE-L11, PA-38, FA-15: see Still to do.
A9: Open | B9: 73 | C9: =COUNTIF('Bugs Now'!$G$5:$G$141,"Open") -> 1 | D9: CORE-M7 (holiday approvals need a database rule).
A10: Was wrong (not a real bug) | B10: 4 | C10: =COUNTIF('Bugs Now'!$G$5:$G$141,"Was wrong") -> 4
A11: Open or partly fixed, Critical/High | B11: 2 | C11: =COUNTIFS('Bugs Now'!$G$5:$G$141,"Open",'Bugs Now'!$B$5:$B$141,"Critical")+COUNTIFS('Bugs Now'!$G$5:$G$141,"Open",'Bugs Now'!$B$5:$B$141,"High")+COUNTIFS('Bugs Now'!$G$5:$G$141,"Partly fixed",'Bugs Now'!$B$5:$B$141,"Critical")+COUNTIFS('Bugs Now'!$G$5:$G$141,"Partly fixed",'Bugs Now'!$B$5:$B$141,"High") -> 0
A12: Security (33: 30 from 23 Oct + 3 from 24 Oct)
A13: Fixed | B13: 2 | C13: =COUNTIF('Security Now'!$F$6:$F$38,"Fixed") -> 27 | D13: Batches 1–3 applied and server functions redeployed.
A14: Partly fixed | B14: 1 | C14: =COUNTIF('Security Now'!$F$6:$F$38,"Partly fixed") -> 4 | D14: C1 and L10 wait on you; H3 needs private buckets; N3 needs the repo copy updated.
A15: Open | B15: 28 | C15: =COUNTIF('Security Now'!$F$6:$F$38,"Open") -> 0
A16: Info / needs check | B16: 2 | C16: =COUNTIF('Security Now'!$F$6:$F$38,"Info*") -> 2
A17: Open or partly fixed, Critical/High | B17: 6 | C17: =COUNTIFS('Security Now'!$F$6:$F$38,"Open",'Security Now'!$B$6:$B$38,"Critical")+COUNTIFS('Security Now'!$F$6:$F$38,"Open",'Security Now'!$B$6:$B$38,"High")+COUNTIFS('Security Now'!$F$6:$F$38,"Partly fixed",'Security Now'!$B$6:$B$38,"Critical")+COUNTIFS('Security Now'!$F$6:$F$38,"Partly fixed",'Security Now'!$B$6:$B$38,"High") -> 2 | D17: C1 (your task) and H3.
A18: New issues (37 found 24 Oct evening)
A19: Fixed | B19: 16 (waiting for Push origin) | C19: =COUNTIF('New Issues'!$G$5:$G$41,"Fixed") -> 35
A20: Partly fixed | B20: 0 | C20: =COUNTIF('New Issues'!$G$5:$G$41,"Partly fixed") -> 1 | D20: SEC-N3: repo copy of the Xero function.
A21: Open | B21: 15 | C21: =COUNTIF('New Issues'!$G$5:$G$41,"Open") -> 1 | D21: CP-NEW-1 (OneDrive "Connected" check).
A22: Andy to decide | B22: 3 | C22: =COUNTIF('New Issues'!$G$5:$G$41,"Andy to decide") -> 0 | D22: Contra to Xero decided and done (minus line).
A23: Needs check | B23: 3 | C23: =COUNTIF('New Issues'!$G$5:$G$41,"Needs check") -> 0
A24: Finance ↔ Projects links (88)
A25: Working | B25: 30 | C25: =COUNTIF('Finance-Projects Map v3'!$J$5:$J$92,"Working") -> 40 | D25: 13 links changed: materials ↔ PO links, calendars, proof of works, retention dates, Getting Started.
A26: Partial | B26: 19 | C26: =COUNTIF('Finance-Projects Map v3'!$J$5:$J$92,"Partial") -> 20
A27: Broken | B27: 4 | C27: =COUNTIF('Finance-Projects Map v3'!$J$5:$J$92,"Broken") -> 4
A28: Missing | B28: 29 | C28: =COUNTIF('Finance-Projects Map v3'!$J$5:$J$92,"Missing") -> 18 | D28: See the map page and Proposals.
A29: Needs check | B29: 6 | C29: =COUNTIF('Finance-Projects Map v3'!$J$5:$J$92,"Needs check") -> 5
A30: Not needed | B30: 0 | C30: =COUNTIF('Finance-Projects Map v3'!$J$5:$J$92,"Not needed") -> 1 | D30: L43 (SoW waste → yard).
A31: Still to do
A32: Items on the list | B32: n/a | C32: =COUNTA('Still to do'!$B$5:$B$36) -> 32
A33: …your tasks | B33: n/a | C33: =COUNTIF('Still to do'!$D$5:$D$36,"You (Andy)") -> 5 | D33: 3 now + 2 waiting for you to ask.
A34: Blue = typed in from v2. Black = worked out live from the other tabs (they update if you change a status).
A36: What you need to do
A37: 1. Turn on leaked-password protection | B37: Supabase › Authentication › Attack Protection. One switch (SEC-L10).
A38: 2. Reconnect OneDrive and revoke the old Microsoft sessions | B38: The database now hides the tokens, but old ones may have been read before 25 Oct (SEC-C1). Admin Centre › Integrations, then Microsoft Entra › Revoke sessions.
A39: 3. Press Push origin for the 26–27 Oct changes, if you haven't | B39: Send pop-up, invoice jobs, purchase invoices table, driver time off, laptop polish, Sales column.
A41: What's left (top of the Still to do tab)
A42: Private file storage (SEC-H3) | B42: Files are limited to your company in the app, but a file's exact web link still opens for anyone.
A43: Repo copy of the Xero function (SEC-N3) | B43: Copy the live version in, so a redeploy can't undo the contra line.
...

Sheet Changes since v2
A1: Changes since v2 (24 Oct evening) up to 27 Oct morning
A2: Everything up to the 27 Oct change is on your laptop. "Live" = pushed (or a database/server change, live straight away). "Live after Push origin" = on the laptop; it goes live when you press Push origin, if you haven't already.
A4: Date | B4: Area | C4: What changed | D4: Where to see it | E4: Live? | F4: Evidence
A5: 25 Oct | B5: Whole app | C5: Fix round 2, core: links that could run a script are closed; "Remember me" keeps the email only; big lists load in pages; bank holidays after 2028; offline page; admin console stays signed in on a bad signal. | D5: Everywhere | E5: Live | F5: 499b04b; out/fix2/core-done.md
A6: 25 Oct | B6: Projects | C6: Fix round 2: 36 Projects bugs fixed (reports, briefings, price builder, templates, RAMS/COSHH builders, permits, check-in, snags, certificates, inductions, schedule). | D6: Projects pages | E6: Live | F6: 160eed7; out/fix2/projA-done.md
A7: 25 Oct | B7: Projects | C7: Fix round 2: materials, HAVS, LOLER, one-person messages, PPE PDF, deliveries; a job link with a made-up job id now goes home. | D7: Projects pages | E7: Live | F7: 7579042; out/fix2/projB-done.md
A8: 25 Oct | B8: Finance | C8: Fix round 2: lists load in pages, retention "still held" everywhere, records in Xero protected, number clashes retried, stuck inbox invoices recovered. | D8: Finance pages | E8: Live | F8: c473337; out/fix2/finance-done.md
A9: 25 Oct | B9: Database | C9: Integrity: duplicate numbers refused, file paths checked for safety (H1/H2), search path fixed (L3), contra column for subcontract payments. | D9: — | E9: Live (database) | F9: sec_round2_a_integrity
A10: 25 Oct | B10: Security | C10: Security batch 1: OneDrive tokens server-only (C1), price files (H4), check-ins (H5), manager-only approvals (H6), company settings admin-only (M2), profile guard (M3), sign as yourself (M4), prices (M5). | D10: — | E10: Live (database) | F10: /home/claude/sql/1 - OpHUB security batch (25 Oct).sql
A11: 25 Oct | B11: Security | C11: Batch 2: materials/PO lock, delivery dates, delivery problem, invoice query, new message types. | D11: — | E11: Live (database) | F11: /home/claude/sql/2 - OpHUB materials and orders (25 Oct).sql
A12: 25 Oct (confirmed 27 Oct) | B12: Security | C12: Batch 3: files readable only inside your company (H3, buckets still public), shared folders per company (M6), webapp storage closed (M9), yard cost edits (M11), function access (L1, L2), device id fix (L4), orphan deletes (L6), clients kept out of company lists (M1), Finance project checks (N2). | D12: — | E12: Live (database) | F12: /home/claude/sql/3 - OpHUB security batch 3 (25 Oct).sql; ea36726
A13: 25 Oct | B13: Server | C13: 15 server functions redeployed: email links and daily limits, OneDrive upload checks, password reset limit, website allow-list, finance inbox (key header, supplier check), Xero v10 (split bills per project and the contra line). | D13: — | E13: Live (server) | F13: claude/OpHUB edge function deploy - 25 Oct 2026 evening.md
A14: 25 Oct | B14: Finance › Applications | C14: Proof of works: the Schedule of Works report goes with the application PDF, Excel and email (whole schedule, or photos since the last application). | D14: Application › Download PDF / Excel / Email | E14: Live | F14: 6d0375b; 9219zo
A15: 25 Oct | B15: Calendars | C15: Application dates show on the site and all-projects calendars for PMs, admins, estimators and QSs. | D15: Job calendar; all-projects calendar | E15: Live | F15: 6d0375b; 9219zp
... A43: Decided | B43: Back button | C43: FB-21: the "up one level" Back is for managers only. | D43: Projects pages | E43: Live | F43: c473337 (9219v:264)

Sheet Bugs Now
A1: Bugs Now: the 137 bugs, status on 27 Oct
A2: Every v2 row carried forward. Status now is only "Fixed" where a fix report or commit backs it up. Open first, then worst first.
A4: ID | B4: Severity | C4: Part of app | D4: Area | E4: Title | F4: Status in v2 | G4: Status now | H4: What changed | I4: Fixed on | J4: Evidence (done report / commit / file:line) | K4: v2 evidence | L4: v2 note
A5: CORE-M7 | B5: Medium | C5: Core 000-260 | D5: Leave approval and limits only checked in the client | E5: status:'approved' (admin or sick), the allowance check and the "max off at once" check are all decided in the browser. hrDecide is a plain d | F5: Open | G5: Open | H5: Not changed. Holiday approvals and limits are still only checked in the app; needs a database rule. | J5: core-done: "Not done (server only)"; hr_leave is not in security batches 1-3 | K5: 186-hr.js:174 dbInsert with status from the browser; 196 plain dbUpdate of status/decided_by | L5: Server-side trigger/RLS is Needs check.
A6: CORE-M3 | B6: Medium | C6: Core 000-260 | D6: Device lock only checked in the client | E6: signIn() saves the session to storage before the device-lock check. The lock is only checked at sign-in and app open, and nothing else (chec | F6: Open | G6: Partly fixed | H6: The app now saves the sign-in only after the device check passes. The server still doesn't check the device when someone checks in. | I6: 25 Oct | J6: core-done: 070:37-56, 050:105, 140:144/158, 150:94-108 (499b04b). Server part not done. | K6: 070-auth.js:50-51 saves SESSION before the device-lock check at 140:142-151 | L6: Nothing on the server enforces it (no SQL in repo).
A7: FA-15 | B7: Medium | C7: Finance 900-9219h | D7: Finance › Team (permissions) | E7: "Give Finance" quietly promotes the person to PM, and switching Finance off doesn't undo it | F7: Partly fixed | G7: Partly fixed | H7: Switching Finance off puts the old role back, but only on the device that gave Finance. The database column for it now exists; the app doesn't use it yet. | I7: 25 Oct | J7: finance-done: 908:218, 900:502 (localStorage); profiles.finance_prev_role added 25 Oct but unused (900:496 comment) | K7: 908:216-235 asks first ("also makes them a manager") and puts the old role back if Finance doesn't switch on. This covers the silent RLS refusal too, because 900:435 returns without setting finance_enabled. | L7: Switching Finance off still doesn't restore the earlier role, and the role is still changed before Finance access is confirmed.
A8: CORE-L11 | B8: Low | C8: Core 000-260 | D8: Malformed % in the URL crashes the page | E8: decodeURIComponent on from / reset parameters isn't wrapped in try/catch. | F8: Open | G8: Partly fixed | H8: Fixed on the sign-in and Team pages. The Schedule of Works page can still crash on a cut-off link. | I8: 25 Oct | J8: core-done: 140:21-23, 260:941; still open at 480:854 | K8: 260:937 and 140-login.js:21 decodeURIComponent without try/catch
A9: PA-38 | B9: Low | C9: Projects 270-589 | D9: Main contractor tiles | E9: MC tile hiding and the induction count | F9: Open | G9: Partly fixed | H9: The induction count is right now. Hidden tiles can still be opened by a direct link. | I9: 25 Oct | J9: projA-done: 510:66; route gating in 890 not done (no mc_hidden_tiles check in 890) | K9: 510:55, 62 counts every completion row, including leavers and repeats
A10: CORE-C1 | B10: Critical | C10: Core 000-260 | D10: XSS / navigation | E10: The header back arrow is built as onclick="goBack('${opts.back}')" with no escaping. opts.back can come from (a) the ?from= query on #/team, | F10: Partly fixed | G10: Fixed | H10: Every back arrow, tab bar and sidebar link is now checked or escaped, and a job link with a made-up job id goes back home. Small gap left: in Finance-only companies the job's Finance link skips the new job check. | I10: 25 Oct | J10: core-done: 130:104-184, 125:81, 260:941, 200:~205 (499b04b); projB-done: 890:229-250 (7579042) | K10: 130-shell.js:141 now goBack('${jsAttr(opts.back)}'). 260:937 and 480:854 still decodeURIComponent(from) with no check. 130:180 go('${t.href}') and 125:81 go('${i.go}') are still unescaped. | L10: The no-tap ?from= XSS is closed. The tab bar is still open: the route site id is never checked against SITES (890:202–203), and pages such as renderVariations (800:142) pass it to tabbar(). So #/site/x'-alert(1)-'/snagging/variations should still run script when any bottom tab is tapped (Needs check in Safari/Chrome: ' is not percent-encoded in a fragment). Use jsAttr in tabbar and the desktop sidebar too.
A11: CORE-H1 | B11: High | C11: Core 000-260 | D11: Stored XSS | E11: Device Locks puts d.device_id raw into onclick="approvePendingDevice('…')" / unlockDevice('…'). The device id is chosen by the client: getDe | F11: Fixed | G11: Fixed | H11: Fixed before v2. | I11: 24 Oct | K11: 260:910, 911, 920 now use jsAttr(d.device_id) | L11: Client side only. Whether check_device_lock_v2 checks the id's format is still Needs check (no SQL in repo).
A12: CORE-H2 | B12: High | C12: Core 000-260 | D12: XSS / broken button (superadmin) | E12: onclick="resetPassword('${escapeHtml(p.email)}')" uses escapeHtml inside a JS string. The browser turns &#39; back into ' before running the | F12: Fixed | G12: Fixed | H12: Fixed before v2. | I12: 24 Oct | K12: admin.html:485 resetPassword('${jsAttr(p.email)}') | L12: admin.html's own jsAttr (line 221) still doesn't escape \n / \r like the app's _jsEsc (030:194). That's minor, because an email address can't contain a newline.
A13: FA-01 | B13: High | C13: Finance 900-9219h | D13: Settings / invoice numbering | E13: Saving Finance settings can wind the invoice counter back, giving duplicate invoice numbers | F13: Fixed | G13: Fixed | H13: Fixed before v2. | I13: 24 Oct | K13: 900:158-160, 173. The invoice and job counters are only sent when the box differs from its defaultValue (or when there is no settings row or job number yet). The 9219o:85-99 wrapper still calls the base save. | L13: Someone can still type a lower number on purpose. There is no server-side floor (RPC or conditional update) as the finding suggested.
A14: FA-03 | B14: High | C14: Finance 900-9219h | D14: Purchase invoice inbox (auto-filing) | E14: Two people (or a phone and a computer) opening Finance at once file the same emailed invoice twice | F14: Fixed | G14: Fixed | H14: Fixed before v2. | I14: 24 Oct | K14: 9219b:56, 66 and 92-93. Each write is conditional on the row still being new: dbUpdate('fin_inbox', id+'&status=eq.new', …). The {status:'filed'} claim happens before the insert, and the item goes back to new if the insert fails (9219b:97). | L14: This is client-side only. There is still no unique index on purchase_invoices (DB check), so a browser that dies between claim and insert leaves the item "filed" with no invoice. See NEW-04 for a misleading toast.
A15: FA-04 | B15: High | C15: Finance 900-9219h | D15: Reports › Cash flow forecast | E15: The cash flow forecast counts money in without VAT and money out with VAT | F15: Fixed | G15: Fixed | H15: Fixed before v2. | I15: 24 Oct | K15: 913:87 uses finInvOutstanding(i) (gross) for invoices. Applications are ×1.2 when standard-rated, suppliers use total. | L15: All columns now include VAT.
A16: FA-05 | B16: High | C16: Finance 900-9219h | D16: The job "book" and reports | E16: Large lists are probably cut off at 1,000 rows, which silently drops costs from jobs and reports | F16: Open | G16: Fixed | H16: Finance lists now load in pages of 1,000 with no cap. (Assumes the server's row cap is 1,000 or more.) | I16: 25 Oct | J16: finance-done: 900:38 finSelectAll; 911:14 and 15 other files | K16: 911:20-36 (limit=5000/10000/20000/50000), 9219b:111-115, 9219:97-101, 9219zi:19. dbSelect (060:88-122) never pages. There is no dbSelectAll anywhere. | L16: It doesn't bite yet: live data is 51 sign-ins and 10 purchase invoices in total. It still needs paging, or a server-side aggregate, before real volumes arrive.
A17: FA-06 | B17: High | C17: Finance 900-9219h | D17: Subcontract applications (CIS) | E17: CIS on subcontractor applications is worked out after contra charges are taken off | F17: Fixed | G17: Fixed | H17: Fixed before v2. | I17: 24 Oct | K17: 912:210-228: gross = net + contraNow, labour = gross − newMat, cis = labour × rate. 912:279-283 stores gross and labour before the contra on fin_sub_payments. | L17: The fix introduced a problem: NEW-01. The deployed Xero push_sub_payment now posts a bill that includes the contra, so Xero leaves the contra amount owing.
A18: FB-01 | B18: High | C18: Finance 9219i-922 | D18: Finance lists: automatic totals bar, Title Case and column filters | E18: Totals-bar observer re-triggers itself every 60 ms, forever | F18: Fixed | G18: Fixed | H18: Fixed before v2. | I18: 24 Oct | K18: 9219x:114-117: the observer ignores mutations inside .finautofoot/.finsfoot/.fcf-row/.navcrumbs and added nodes of those classes.
A19: FB-02 | B19: High | C19: Finance 9219i-922 | D19: Applications for payment: autosave | E19: Application autosave doesn't record what it saved, so the next redraw throws away unsaved changes (e.g. "Use site progress") | F19: Fixed | G19: Fixed | H19: Fixed before v2. | I19: 24 Oct | K19: 9219ze:36: after a successful PATCH, finApp.__loaded is set to the returned updated_at, so 902:494 keeps the in-memory copy. 9219ze:76-81 queues an autosave after "Use site progress". | L19: A tiny race remains: a render that lands while an autosave is still in flight can still reload.
A20: FB-03 | B20: High | C20: Finance 9219i-922 | D20: Variations register ↔ draft applications | E20: Draft application counts a site variation twice after it is imported into the register | F20: Fixed | G20: Fixed | H20: Fixed before v2. | I20: 24 Oct | K20: 9219s:269-273 links variation_id-only rows to their register copy (sets fin_variation_id) before deciding what to add.
A21: FB-04 | B21: High | C21: Finance 9219i-922 | D21: Application / Certificate summary after certification | E21: Certified applications show wrong "Certified" figures in the summary (£0 on older certificates; variations taken from the previous certificate) | F21: Fixed | G21: Fixed | H21: Fixed before v2. | I21: 24 Oct | K21: 9219p:941-969 (fix 16): when cert_net is set, the Certified column comes from cert_gross/cert_discount/cert_retention/cert_previous/cert_net. Line splits come from cert_lines when present, otherwise a dash. 9219p:971-979 reads the application's own cert_lines for vars and days.
A22: FB-05 | B22: High | C22: Finance 9219i-922 | D22: Whole app (statements reader) | E22: A regex lookbehind in the statements file can stop the whole app loading on older iPhones | F22: Fixed | G22: Fixed | H22: Fixed before v2. | I22: 24 Oct | K22: 9219l:39-40: the lookbehind is built with new RegExp inside try/catch, with a fallback. No other lookbehind literal is left in src/js (grep).
A23: PB-01 | B23: High | C23: Projects 590-890 | E23: H&S Policy sign-in gate re-appears on every app launch after the annual re-sign | F23: Fixed | G23: Fixed | H23: Fixed before v2. | I23: 24 Oct | K23: 640:143 sigs.filter(s=>s.user_id===ME.id).pop() (newest)
A24: CORE-M1 | B24: Medium | C24: Core 000-260 | D24: Token / secret handling | E24: Integrations loads onedrive_connections with select=* (no column list) just to check odConn.access_token. Any admin's browser therefore rece | F24: Fixed | G24: Fixed | H24: Fixed before v2. | I24: 24 Oct | K24: 260:112 select=org_id,account_email,folder_path,connected_at; 260:286 tests odConn only | L24: Column grants on the token columns are still Needs check (server). Devices that opened Integrations before the fix still have the full row cached (see NEW-2).
A25: CORE-M2 | B25: Medium | C25: Core 000-260 | D25: Remember-me password | E25: "Remember my email & password" stores the password in plain text in localStorage.ophub_remember. doSignOut never clears it, and the login fo | F25: Open | G25: Fixed | H25: "Remember me" now keeps the email only. Any old saved password is wiped when the app starts. | I25: 25 Oct | J25: core-done: 040:44-60, 140:76-135, 070:80 (499b04b) | K25: 140-login.js:133 stores {email, password}; 140:74 pre-fills the password; 070:66-80 doSignOut never removes ophub_remember
A26: CORE-M4 | B26: Medium | C26: Core 000-260 | D26: Wrong counts (roster includes people who can't sign) | E26: The RAMS "outstanding" roster is every site_assignments user (operatives plus clients, drivers, site managers, PMs). Clients are view-only a | F26: Open | G26: Fixed | H26: RAMS "outstanding" now lists operatives only. | I26: 25 Oct | J26: core-done: 190:113-115, 200:114, 230:62 | K26: 190:84 rosterBySite = every assignment (RAMS uses it at 190:113); 200:77-78; 230:39-40, 61 | L26: Only the COSHH roster (190:91-92) is limited to operatives.
A27: CORE-M5 | B27: Medium | C27: Core 000-260 | D27: Data cut off at 1000 rows | E27: These queries have no limit (or a limit above the server cap) and are sorted oldest first. If the project uses Supabase's default max_rows = | F27: Open | G27: Fixed | H27: Check-in, PPE and holiday lists load in pages of 1,000, so nothing is cut off. "On site now" uses the latest check-in. | I27: 25 Oct | J27: core-done: 060:187 dbSelectAll; 260:161/170; 186:100; 185:507. Assumes the server row cap is 1,000 (not confirmed). | K27: 260:159 (checkins, asc, no limit), 260:166, 185:505 (asc, no limit), 186:65 limit=2000 | L27: dbSelectNet (060:105) does no paging.
A28: CORE-M6 | B28: Medium | C28: Core 000-260 | D28: Signed out because storage is full | E28: On the web, every successful dbSelect response (up to 300 whole result sets), the signed-link map (up to 4000 URLs) and the boot snapshot al | F28: Open | G28: Fixed | H28: If the phone's storage is full, the app clears old saved copies so the sign-in still saves. | I28: 25 Oct | J28: core-done: 050:105 persistSession; 060:57-89 | K28: 050:76 await setJSON(K_SESSION…) result not checked; 040:39 sset returns false/null on failure; 060:21 cap is 300 entries, not bytes
A29: CORE-M8 | B29: Medium | C29: Core 000-260 | D29: Calendar export on the phone app | E29: deliverIcsFile calls window.open(publicUrl('site-photos', …), '_system'). Once site-photos is private, the 065 wrapper opens about:blank fir | F29: Open | G29: Fixed | H29: Calendar files open through a signed link and never leave a blank page. | I29: 25 Oct | J29: core-done: 060:605-608, 065:184-197 | K29: 060:505 window.open(publicUrl('site-photos', stored), '_system'); 065:181 falls back to location.href = u | L29: The 065 wrapper runs even while the bucket is public (065:17-18), so this can happen now whenever no signed link is cached.
A30: FA-08 | B30: Medium | C30: Finance 900-9219h | D30: Retention card, Sales › Retention, the retention ledger, forecast retHeld, and the home tile "Retention held by clients" | E30: "Retention held" never goes down after retention release invoices | F30: Partly fixed | G30: Fixed | H30: "Still held" retention is used everywhere: home tile, ledger and reports. | I30: 25 Oct | J30: finance-done: 911:170, 913:64, 914:91 | K30: New finRetentionReleased / finRetentionStillHeld at 903:151-156. Used by the project tile (9219n:210, 9219q:37), the Retention card (9219n:263), Sales › Retention (9219:140) and the Detailed Summary (9219v:39). | L30: Still gross held in three places: the home "Retention held by clients" (914:89-90), the Retention ledger report (913:64) and the forecast/overview retHeld (911:168, which feeds the 913 overview "Retention held" column).
A31: FA-09 | B31: Medium | C31: Finance 900-9219h | D31: Applications | E31: After an earlier certificate comes in lower, a later submitted application shows a different amount due on screen than in its stored figures and Excel, and "Email again" silently rewrites it | F31: Fixed | G31: Fixed | H31: Fixed before v2. | I31: 24 Oct | K31: 902:496-500: a locked application uses the stored a.previous, and only drafts recompute it. There is an orange note when the live figure differs. 902:822: "Email again" only saves drafts. The 9219p:74/388 saves need #finAppSave, which a locked application doesn't render (902:552). The 9219ze autosave is off when locked (9219ze:10).
A32: FA-10 | B32: Medium | C32: Finance 900-9219h | D32: Xero sync (sales invoices) | E32: Xero works out VAT line by line, OpHUB on the whole invoice, so totals can differ by a penny or two | F32: Fixed | G32: Fixed | H32: Fixed before v2. | I32: 24 Oct | K32: 901:30-33 rounds VAT per line (finRound(a*c.r/100)) before summing, as Xero does. | L32: Old issued invoices are recomputed on screen from their lines and may now show 1p different from their stored total. The deployed edge function's 2p warning threshold is unchanged.
A33: FA-11 | B33: Medium | C33: Finance 900-9219h | D33: Xero sync (bills, operative invoices) | E33: Records already in Xero can still be changed, cancelled or rejected in OpHUB, leaving Xero out of step | F33: Partly fixed | G33: Fixed | H33: Changing a record already in Xero is blocked unless you confirm you will change Xero too; with no signal it stops. | I33: 25 Oct | J33: finance-done: 904:314-332, 910:169, 9219g:211-220, 917:127-207 | K33: It warns rather than blocks. finXeroPostedConfirm (904:312-317) is used for Reject (904:319), line coding (9219g:189-190), and operative invoice Save and Cancel (9219g:203-222). | L33: Edit, Cancel and Reject are still possible on records already in Xero, and nothing is pushed to Xero. The Split / allocate pop-up (917 openFinSplit) still has no warning.
A34: FA-12 | B34: Medium | C34: Finance 900-9219h | D34: Invoices | E34: The Sales page deletes anyone's brand-new invoice draft while they are still typing it | F34: Fixed | G34: Fixed | H34: Fixed before v2. | I34: 24 Oct | K34: 9219:82-90 only deletes empty drafts that are yours and over 24 h old, or anyone's over 7 days. 901:211 and 232 toast "This draft no longer exists" when the update matches 0 rows. | L34: Side effect, see NEW-05: young empty drafts are hidden from the list but not deleted.
A35: FA-13 | B35: Medium | C35: Finance 900-9219h | D35: Labour / job costs | E35: Materials supplied by operatives are never charged to any job | F35: Fixed | G35: Fixed | H35: Fixed before v2. | I35: 24 Oct | K35: 911:75-86 adds a "Materials supplied by operative" cost line (cat materials), shared by labour value across the invoice's job lines. It feeds the costs ledger, forecast and reports. | L35: The Labour card (finJobLabour, 9219c) leaves it out on purpose.
A36: FA-14 | B36: Medium | C36: Finance 900-9219h | D36: Subcontract CIS | E36: Marking a subcontract application paid doesn't check that its CIS record was saved | F36: Fixed | G36: Fixed | H36: Fixed before v2. | I36: 24 Oct | K36: 912:268-296 checks for an existing CIS row with dbSelectChecked and inserts fin_sub_payments first. The application is only marked paid after that row saves. A paid application with no CIS row gets an "Add it to the CIS return" button (912:203-207). | L36: There is no unique index on fin_sub_payments(sub_app_id) (DB check). The once-guard covers double taps.
A37: FA-16 | B37: Medium | C37: Finance 900-9219h | D37: Numbering | E37: Application, variation and subcontract numbers are worked out in the browser as "last + 1", so two people can get the same number | F37: Partly fixed | G37: Fixed | H37: Numbers retry if someone takes the same one at the same moment, and the database now refuses duplicates. | I37: 25 Oct | J37: finance-done: 912:100, 911:393, 9219s:244; unique indexes applied 25 Oct | K37: Applications: 902:460-476 retries on 409, backed by DB unique fin_applications_site_id_number_key, so this part works. Variations: 9219s:326-345 renumbers after the insert if it finds a clash. Subcontracts / sub applications: 912:93-109 retry on 409. | L37: There are no unique indexes on fin_variations(site_id,seq), fin_subcontracts(site_id,seq) or fin_sub_apps(subcontract_id,number) (DB check), so the 912 retry never fires. The variation check-and-renumber can still race three ways. Day works (saveFinDaywork) are not covered.
A38: FA-17 | B38: Medium | C38: Finance 900-9219h | D38: Wage pushes / PM Price tile | E38: Wage pushes booked on a price are never removed from that price when withdrawn, and re-sending books them twice (dormant in trial) | F38: Fixed | G38: Fixed | H38: Fixed before v2. | I38: 24 Oct | K38: 9217:44-58 finWagePushWithdraw sets the push to withdrawn and amount 0, and zeroes its price entry (with a roll-up when there is no price sheet). It is used by 9217:36 and 9219c:236. 9217:105-113 locks the buttons while booking and re-reads the push (dbSelectNet, status must be pending). | L38: A re-book creates a new entry; the old one stays at £0, so nothing is double-counted.
A39: FA-18 | B39: Medium | C39: Finance 900-9219h | D39: Project summary / reports | E39: The forecast's "Expected final value" includes variations not yet agreed, but the label says agreed only | F39: Partly fixed | G39: Fixed | H39: Labels now say the forecast includes submitted variations, and show how much. | I39: 25 Oct | J39: finance-done: 911:223, 9219zm:43/88, 9219q, 9219zj:64 | K39: Only the 913 report column labels changed: "(incl. submitted variations)" at 913:28, 33 and 38. | L39: Still in place: 911:142 ffa = contract + vAgreed + vPending and 911:221 "Contract plus agreed variations". New instance: 9219zj:64 headline subline (NEW-02).
A40: FA-19 | B40: Medium | C40: Finance 900-9219h | D40: Retention | E40: Retention release invoices ignore later certificates that change the amount held | F40: Fixed | G40: Fixed | H40: Fixed before v2. | I40: 24 Oct | K40: 903:139-147 finRetHalfAmt: the second half is held minus the first-half invoice's net, and an invoiced half shows its invoice amount. Used in 903:204 (raise) and 9219n:264 (card). If nothing is left to release, raising says so (903:205).
A41: FA-20 | B41: Medium | C41: Finance 900-9219h | D41: Job finance page / plant | E41: The first job-cost card on the project page counts plant hire twice when its cost comes from the hire company's invoices | F41: Partly fixed | G41: Fixed | H41: Plant hire costed from the hire company's invoices is no longer counted twice. | I41: 25 Oct | J41: finance-done: 900:278, 917:90 | K41: 910:229-245 wraps finPlantCardHtml to leave invoice-costed hires out of "Plant to date". | L41: Still unfiltered: 900:229 (hires.reduce(...finPlantCost) in the first job-cost card) and 917:89 (FIN_SPLIT_TABLES.fin_plant_hires.net, the value in the split pop-up).
...

Sheet Security Now
A1: Security Now: 30 items from 23 Oct + 3 found on 24 Oct
A2: Based on the database and server state confirmed on 27 Oct: integrity fixes, security batches 1–3 applied, and the 25–26 Oct server function deploys.
A3: Still manual for you: turn on leaked-password protection, and reconnect OneDrive / revoke the old Microsoft sessions.
A5: ID | B5: Severity | C5: Area | D5: Title | E5: Status in v2 | F5: Status now | G5: What changed | H5: Fixed on | I5: Evidence (batch / deploy / file) | J5: Left to do | K5: v2 evidence | L5: Found
A6: SEC-C1 | B6: Critical | C6: RLS / OAuth token handling | D6: OneDrive access/refresh tokens readable by every member of the company (and cached on phones) | E6: Partly fixed | F6: Partly fixed | G6: Only the server can read the tokens now (database batch 1), and the app no longer fetches them. Left for you: reconnect OneDrive and revoke the old Microsoft sessions. | H6: 25 Oct | I6: security batch 1: C1 column grants; core-done 060 cache purge | J6: You: reconnect OneDrive; revoke old sessions | K6: App: 380-assign-team…:12 now uses select=org_id, and odCompanyConnected = odConnRows.length>0 (:21). 260-admin-centre-layout.js:112 selects only org_id,account_email,folder_path,connected_at. DB unchanged: policy onedrive_connections."select own org" is still USING (org_id = (SELECT my_org_id())). authenticated still has full table grants (SELECT, INSERT, UPDATE, DELETE…), and the 1 live connection still holds an access token. Anyone in the company can still call GET /rest/v1/onedrive_connections?select=access_token. The old app's cached response is also still on devices (see N1). The token should be treated as already exposed until it is rotated. | L6: 23 Oct
A7: SEC-H3 | B7: High | C7: Storage | D7: Cross-company read of every file in the public buckets (signatures, incident photos, expense receipts, RAMS/COSHH, company policies, drawings) | E7: Open | F7: Partly fixed | G7: Listing and opening files is now limited to your own company. The buckets are still public, so anyone with a file's exact link can open it. | H7: 25 Oct (batch 3, confirmed 27 Oct) | I7: security batch 3: H3 | J7: Make the buckets private and use signed links (app + database) | K7: All 9 buckets are still public=true (signatures, incident-photos, site-photos, rams-docs, coshh-docs, coshh-library, mc-documents, drawings, operative-tools). The 9 "signed-in read <bucket>" policies still read USING (bucket_id = '<bucket>') with no org check. 1 profile with no org still exists. | L7: 23 Oct
A8: SEC-L10 | B8: Low | D8: Leaked-password protection off; password-reset endpoint not rate limited | E8: Open | F8: Partly fixed | G8: Password reset emails are limited to 3 per address per hour. Left for you: turn on leaked-password protection. | H8: 25 Oct | I8: edge deploy 25 Oct: send-password-reset v1 → v2 | J8: You: turn on leaked-password protection | K8: Advisor auth_leaked_password_protection is still WARN. send-password-reset is v1, unchanged. | L8: 23 Oct
A9: SEC-N3 | B9: Info | C9: Edge functions | D9: The xero edge function in the repo differs from the deployed one | E9: Open | F9: Partly fixed | G9: Xero v10 is live. The repo copy is older than what is live; copy the live version in. | H9: 25 Oct | I9: edge deploy 25 Oct; supabase/functions/xero/index.ts differs from the live source | J9: Copy the live xero (and finance-inbox) source into the repo | K9: The FA-28 change (one Xero line per project when a bill is split) isn't live. I found no security problem in the new code: the extra sites lookup is .eq('org_id', orgId). But the I1 conclusion ("deployed matches repo") no longer holds for this function. | L9: New
A10: SEC-I2 | B10: Info | D10: Needs check (not individually read) | E10: Info / needs check | F10: Info / needs check | G10: 11 email functions were reviewed and hardened on 25 Oct. The other send/notify functions were not re-checked. | I10: edge deploy 25 Oct | J10: Review the remaining send-*/notify-* functions | K10: Not re-read. Note: the repo supabase/functions/xero/index.ts changed on 24 Oct (FA-28, bill split per project), but the deployed function is still v9 (21 Oct). See N3. | L10: 23 Oct
A11: SEC-I1 | B11: Info | D11: Things checked and found OK | E11: Info / needs check | F11: Info | G11: Not re-checked. | K11: The "checked and OK" list still holds. The new client code follows the same pattern (section 4). | L11: 23 Oct
A12: SEC-H1 | B12: High | C12: Client XSS + RLS | D12: Stored XSS through organizations.logo_path (runs for the whole company and in the superadmin console) | E12: Fixed | F12: Fixed | G12: App side (v2) plus the database check on logo paths. | H12: 25 Oct | I12: path-safe check constraints (H1/H2) applied 25 Oct | K12: 100-state.js:302 URL-encodes each path segment. encodeURIComponent encodes ", <, > and spaces, and every orgLogoUrl() use is a double-quoted src="…" (125:112, 130:125, 140:85, 150:65, 170:59, 260:233, 640:156). admin.html:420 uses the same encoding. The other raw publicUrl('org-logos', ORG.logo_path) calls (320:803, 340:1570/1728, 400:1060, 430:1230, 500:561/835, 550:419, 660:868, 800:198, 587:30, 589:692) only fetch() bytes for PDFs and never reach HTML. Still not done: there is no organizations_logo_path_safe CHECK constraint, and "pm update own org branding" is unchanged (see M2). | L12: 23 Oct
A13: SEC-H2 | B13: High | C13: Client XSS | D13: Stored XSS through photo/file storage_path values in src= and onclick= (49 places) | E13: Open | F13: Fixed | G13: The app encodes every file path, and the database refuses unsafe paths. | H13: 25 Oct | I13: core-done: 060:380-383, 065:125; path-safe check constraints applied 25 Oct | K13: 060-offline-read-cache.js publicUrl() still does SUPABASE_URL+'/storage/v1/object/public/'+bucket+'/'+path with no encoding. 46 template sites still interpolate it into src="${publicUrl(…)}" / viewImage('${publicUrl(…)}'), e.g. 340-maintenance-repair-contract.js:913,921, 320-per-operative-certifications.js:502,657, 240-my-signature…:11. No *_paths_safe constraints exist (pg_constraint has none). schedule_photos."insert site access" is unchanged. | L13: 23 Oct
A14: SEC-H4 | B14: High | C14: Storage | D14: Any PM/admin of any company can read every company's price files | E14: Open | F14: Fixed | G14: Price files only for your own company's projects. | H14: 25 Oct | I14: security batch 1: H4 | K14: storage."select price files storage": the first branch is still EXISTS(profiles pr WHERE pr.id = auth.uid() AND pr.role IN ('pm','admin')) with no site or org check. | L14: 23 Oct
A15: SEC-H5 | B15: High | C15: RLS / finance integrity | D15: Check-ins can be forged for anyone, at any time, and they drive pay runs and labour costs | E15: Open | F15: Fixed | G15: You can only check yourself in, at the current time; only managers edit check-ins. | H15: 25 Oct | I15: security batch 1: H5 | K15: checkins."insert site access" WITH CHECK is still has_site_access(site_id), and "update site access" is still has_site_access(site_id) on both sides. There is no user_id/ts check. Pay run still reads these (9218-finance-payrun.js:26, now with a UK-midnight window, but forged rows still count). | L15: 23 Oct
A16: SEC-H6 | B16: High | C16: Client-only role checks | D16: Approval and status fields protected only in the UI (variations, permits, RAMS/COSHH docs, materials) | E16: Open | F16: Fixed | G16: Approval and decision fields on variations, permits, RAMS, COSHH and materials can only be changed by managers. Snags, schedule and site-layout tables still use the general job rule. | H16: 25 Oct | I16: security batch 1: H6 guard trigger (guard_manager_fields) | J16: Optional: same guard on snags, schedule and site layout | K16: variations, permits, rams_docs, coshh_docs and materials UPDATE policies are still has_site_access(site_id) on both sides. There is no guard trigger (none in pg_trigger on those tables). | L16: 23 Oct
A17: SEC-M1 | B17: Medium | C17: RLS | D17: Org-wide SELECT policies don't exclude the client (external customer) role | E17: Open | F17: Fixed | G17: Client logins can't read company-wide lists. A few stay open on purpose because client screens need them (names, H&S policy, tools, toolbox talks). | H17: 25 Oct (batch 3, confirmed 27 Oct) | I17: security batch 3: M1 | K17: report_submissions."org can read submissions" = org_id = my_org_id(), and profiles."select same org profiles" and suppliers."select own org" are unchanged. There are 0 client profiles today, so nobody can exploit this yet. | L17: 23 Oct
A18: SEC-M10 | B18: Medium | C18: Client XSS | D18: JS injection in the superadmin console through a user-editable profile email | E18: Fixed | F18: Fixed | G18: Fixed before v2 (the injection); batch 1 also stops managers changing other people's email. | H18: 24 Oct | I18: v2; security batch 1: M3 / M10 | K18: admin.html:485 is now onclick="resetPassword('${jsAttr(p.email)}')". Still not done: profiles.email is still editable by its owner ("user update own profile", and no trigger keeps it in step with auth.users). That doesn't matter for this sink any more. | L18: 23 Oct
A19: SEC-M11 | B19: Medium | C19: SECURITY DEFINER RPC | D19: yard_cost_edit lets non-finance PMs edit finance job costs and move them to any site | E19: Open | F19: Fixed | G19: Yard cost edits stay inside your company, and only Finance can change the money. | H19: 25 Oct (batch 3, confirmed 27 Oct) | I19: security batch 3: M11 | K19: The yard_cost_edit body is unchanged. It still has no check that p_site belongs to the caller's org (update fin_job_costs set … site_id = coalesce(p_site, site_id)), and PMs can still change net. has_function_privilege('anon', …) is still true. | L19: 23 Oct
A20: SEC-M2 | B20: Medium | C20: RLS | D20: Any PM/site manager can rewrite any column of the company record | E20: Open | F20: Fixed | G20: Only an admin changes the company name, billing, modules, job numbering or expenses email. | H20: 25 Oct | I20: security batch 1: M2 | K20: organizations."pm update own org branding" = is_pm() AND id = my_org_id() on all columns. The only triggers are trg_protect_plan_tier and trg_org_modules_from_tier. | L20: 23 Oct
A21: SEC-M3 | B21: Medium | C21: RLS | D21: PMs can edit other people's profiles, including signature images and roles | E21: Open | F21: Fixed | G21: A manager can't change someone else's signature or email, or make them an admin. | H21: 25 Oct | I21: security batch 1: M3 / M10 | K21: profiles."manager update pm/operative role within org" is unchanged. There is no protect_profile_by_manager trigger: the profiles triggers are estimator_sync, finance_on_insert, protect_profile_finance and protect_profile_role_org. New client code relies on this path: 908-finance-standalone.js:216-235 (finTeamToggle) promotes a user to pm when Finance is granted (it now asks first, :221). | L21: 23 Oct
A22: SEC-M4 | B22: Medium | C22: RLS / H&S records | D22: Signatures can be forged in another person's name | E22: Open | F22: Fixed | G22: You can only sign as yourself. | H22: 25 Oct | I22: security batch 1: M4 | K22: rams_signatures, coshh_signatures and site_layout_signatures "insert site access" WITH CHECK still has only has_site_access(...), with no user_id = auth.uid(). | L22: 23 Oct
A23: SEC-M5 | B23: Medium | C23: RLS | D23: Commercial values readable by operatives and subcontractors (hidden only in the UI) | E23: Open | F23: Fixed | G23: Prices only for managers, Finance and people given price access on that job. | H23: 25 Oct | I23: security batch 1: M5 | K23: pricing_elements."select site access" and price_weeks."select site access" are still just has_site_access(site_id). sites."select assigned or pm" is unchanged, and there is no column revoke. | L23: 23 Oct
A24: SEC-M6 | B24: Medium | C24: Storage | D24: storage_path_mine() shares folders across all companies and lets any member write or delete any site folder | E24: Open | F24: Fixed | G24: Shared folders are kept per company, and only the uploader or a manager of the same company can delete or replace a file. Old shared folders still take new files until phones are updated. | H24: 25 Oct (batch 3, confirmed 27 Oct) | I24: security batch 3: M6 (storage_path_mine, storage_can_change); app commit ea36726 | K24: storage_path_mine() body is unchanged: if s1 in ('general','exports','report-pdfs') then return true applies to any signed-in user with an org. It also returns true for s2 = org and for any site folder of the caller's org, whether or not they are assigned to it. | L24: 23 Oct
A25: SEC-M7 | B25: Medium | C25: Edge functions (email abuse) | D25: Signed-in users can send company-branded email to any address, with any link | E25: Open | F25: Fixed | G25: Email functions redeployed: links must be your own files, and every send is logged and limited per day. | H25: 25 Oct | I25: edge deploy 25 Oct (11 send-* functions); edge_email_log table | K25: send-document-email is still v11, last deployed 16 Oct. Nothing has been redeployed. | L25: 23 Oct
A26: SEC-M8 | B26: Medium | C26: Edge functions | D26: Any member can write or overwrite files anywhere in the company's OneDrive/SharePoint | E26: Open | F26: Fixed | G26: Operatives can only upload to OneDrive for jobs they are on. | H26: 25 Oct | I26: edge deploy 25 Oct: onedrive-upload v29 → v30 | K26: onedrive-upload is still v29, last deployed 14 Oct. | L26: 23 Oct
A27: SEC-M9 | B27: Medium | C27: Storage | D27: webapp bucket: public, and any PM of any company can upload or overwrite | E27: Open | F27: Fixed | G27: Nobody signed in can write to the old "webapp" storage any more. | H27: 25 Oct (batch 3, confirmed 27 Oct) | I27: security batch 3: M9 | K27: webapp is still public with 2 objects. "pm upload webapp" and "pm update webapp" are still bucket_id='webapp' AND is_pm(), with no org check. | L27: 23 Oct
A28: SEC-L1 | B28: Low | D28: SECURITY DEFINER functions executable by anon (39) and trigger functions exposed as RPCs | E28: Open | F28: Fixed | G28: Logged-out visitors can't call database functions (except the invite page), and trigger functions can't be called directly. | H28: 25 Oct (batch 3, confirmed 27 Oct) | I28: security batch 3: L1 | K28: Advisor: anon_security_definer_function_executable 39 and authenticated_security_definer_function_executable 55. The same functions are listed as on 23 Oct, trigger functions included. | L28: 23 Oct
A29: SEC-L2 | B29: Low | D29: check_and_lock_device (v1) still callable alongside v2 | E29: Open | F29: Fixed | G29: The old device check is switched off. | H29: 25 Oct (batch 3, confirmed 27 Oct) | I29: security batch 3: L2 | K29: check_and_lock_device(text): authenticated can still execute it (anon cannot). | L29: 23 Oct
A30: SEC-L3 | B30: Low | D30: Mutable search_path on fin_item_key(text), fin_qty_num(text) | E30: Open | F30: Fixed | G30: Applied. | H30: 25 Oct | I30: sec_round2_a_integrity (search_path) | K30: Advisor function_search_path_mutable: fin_item_key, fin_qty_num. proconfig is null. | L30: 23 Oct
A31: SEC-L4 | B31: Low | D31: Device lock is trivially bypassed | E31: Open | F31: Fixed | G31: An old-style phone id that belongs to someone else no longer lets you straight in. (The device lock is still a deterrent, not a hard lock.) | H31: 25 Oct (batch 3, confirmed 27 Oct) | I31: security batch 3: L4 | K31: The check_device_lock_v2 body still has the fp_ branch. | L31: 23 Oct
A32: SEC-L5 | B32: Low | D32: Finance inbox: key in the URL, and AI auto-filing is exposed to prompt injection | E32: Open | F32: Fixed | G32: The inbox key now goes in a header (the old link form still works), AI-filed invoices are never auto-approved, and a supplier that doesn't match the PO goes to Query. | H32: 25 Oct | I32: edge deploy 25 Oct: finance-inbox v2 → v3 (index.ts:9, 120-159) | J32: Optional: move the mail forwarder to the header, then stop accepting ?key= | K32: finance-inbox is still v2 (21 Oct), with no redeploy. On the client, filing now claims the row first (9219b-finance-purchases.js:96, 906-finance-inbox.js:188). That stops double filing, but the AI auto-filing trust issue is unchanged. | L32: 23 Oct
A33: SEC-L6 | B33: Low | D33: "Orphan row" clauses let any PM on the platform delete orphaned rows of other companies | E33: Open | F33: Fixed | G33: The "orphan row" delete escape hatch is removed. | H33: 25 Oct (batch 3, confirmed 27 Oct) | I33: security batch 3: L6 | K33: 29 policies still contain NOT (EXISTS (SELECT 1 FROM sites …)) orphan branches, e.g. checkins."pm delete", variations."pm delete", pricing_elements."pm delete", price_weeks."pm delete". | L33: 23 Oct
A34: SEC-L7 | B34: Low | D34: Session and offline cache (including finance data) stored in localStorage | E34: Open | F34: Fixed | G34: Finance, wages, OneDrive and Xero data are never saved on the phone. | H34: 25 Oct | I34: core-done: 060:49-53 cacheNeverStore | K34: 060-offline-read-cache.js:46 cacheRows() still caches every dbSelect response with no table exclusions. That now also includes client_pos.files and the new job_finance columns. | L34: 23 Oct
A35: SEC-L8 | B35: Low | D35: Edge function hygiene | E35: Open | F35: Fixed | G35: Functions redeployed with a website allow-list and the other tidy-ups. | H35: 25 Oct | I35: edge deploy 25 Oct | K35: No edge function has been redeployed since 21 Oct, so CORS *, raw error echoes and the Math.random() password in admin-reset-password (v18, 3 Oct) are unchanged. | L35: 23 Oct
A36: SEC-L9 | B36: Low | D36: onedrive-oauth-callback reflects the error parameter into HTML unescaped | E36: Open | F36: Fixed | G36: The OneDrive sign-in page escapes the error text. | H36: 25 Oct | I36: edge deploy 25 Oct: onedrive-oauth-callback v27 → v28 | K36: onedrive-oauth-callback is v27, unchanged since 20 Sep. | L36: 23 Oct
A37: SEC-N1 | B37: Low | C37: Client offline cache / C1 follow-up | D37: OneDrive token responses from the old app are still cached on devices | E37: Open | F37: Fixed | G37: Phones wipe old copies, and the database no longer hands out the tokens. Reconnect OneDrive (under SEC-C1). | H37: 25 Oct | I37: core-done 060:91-111; security batch 1 (C1) | K37: The C1 client fix stops new fetches of the token. Nothing removes the responses the old build already wrote to localStorage. They stay until sign-out or until 300 newer reads push them out. The refresh_token from the admin screen's select=* lasts much longer than an hour. | L37: New
A38: SEC-N2 | B38: Low | C38: RLS, Finance tables used by the new Overview, BoQ and variations screens | D38: Several finance tables don't check that site_id belongs to your company on write (integrity only); contract_value_source is free text | E38: Open | F38: Fixed | G38: Finance rows can only point at your own company's projects. | H38: 25 Oct (batch 3, confirmed 27 Oct) | I38: security batch 3: N2 (site_in_my_org) | K38: A Finance user can save one of their own company's rows against another company's site_id. The other company can't see the row (it's filtered by org), so nothing leaks across companies. But it's inconsistent with the stricter tables, and it lets bad data in (e.g. a pasted wrong UUID). contract_value_source accepts any text. | L38: New

Sheet New Issues
A1: New Issues (found 24 Oct evening): status on 27 Oct
A2: ID prefixes: CP- = Core/Projects re-check, FIN- = Finance re-check, SEC-N = security re-check, NS- = review of the new screens, FX- = review of the fixes.
A4: ID | B4: Source | C4: Severity | D4: Area | E4: Title | F4: Status in v2 | G4: Status now | H4: What changed | I4: Fixed on | J4: Evidence | K4: What was wrong (v2) | L4: Where (file:line, v2) | M4: Same as
A5: CP-NEW-1 | B5: Core/Projects re-check | C5: Low | D5: Admin Centre › Integrations; Assign Team | E5: OneDrive shows "Connected" when any connection row exists (Needs check) | F5: Needs check | G5: Open | H5: Not changed. Integrations shows "Connected" whenever a connection record exists (the app can no longer read the token to check). | J5: core-done: "Not done (needs DB)"; 260:112 and 380:12 now select org_id only | K5: The 24 Oct fix stopped loading access_token, so "connected" now means "a row exists for this org". Before, it meant "a row with a token exists". If the OAuth flow creates the row before the token is stored, or the refresh job blanks the token when Microsoft revokes it, the page now says "Connected — syncing to …". | L5: 260-admin-centre-layout.js:112, 286; 380-assign-team-per-site-pm-allocates-operat.js:12, 21
A6: SEC-N3 | B6: Security re-check | C6: Info | D6: Edge functions | E6: The xero edge function in the repo differs from the deployed one | F6: Open | G6: Partly fixed | H6: The live Xero function is now v10. The copy in the code (repo) is older than what is live, so a redeploy from the repo would undo the contra line. Copy the live version in. | I6: 25 Oct | J6: edge deploy 25 Oct (xero v9 → v10 from /home/claude/edge/xero/new); supabase/functions/xero/index.ts differs | K6: The FA-28 change (one Xero line per project when a bill is split) isn't live. I found no security problem in the new code: the extra sites lookup is .eq('org_id', orgId). But the I1 conclusion ("deployed matches repo") no longer holds for this function. | L6: supabase/functions/xero/index.ts:363-390 (24 Oct, FA-28 split lines). Deployed xero is v9, updated_at 21 Oct. | M6: FX-P10
A7: NS-H1 | B7: New screens review | C7: High | D7: Bill of Quantities on the phone (9219zk) together with the autosave (9219n) | E7: Phone BoQ editor: a new line (or edits) typed while an autosave is running is never saved | F7: Fixed (waiting for Push origin) | G7: Fixed | H7: Fixed on 24 Oct night (tested); live since you pressed Push origin. | I7: 24 Oct (night) | J7: commit 698ae60 | K7: • finBqAddAt (every "+ Add …" on the phone) inserts an empty row and calls finContractAutoSave() immediately, then opens the edit sheet. • The autosave skips the empty row, because it has no description. • When the autosave finishes, though, it takes the "saved" snapshot from the current finContractRows. That snapshot already includes whatever the user has typed into the sheet in the meantime. • When the user taps Done, finBqClose checks finContractIsDirty(), gets false, and does not save. • The same happens to any edit made in the sheet that is reopened after Up/Down (finBqMove → finContractMove → autosave → finBqEdit). • The autosave PATCHes every line one after another, so on a real BoQ it runs for several seconds on mobile. That makes this window easy to hit. | L7: • 9219n-finance-newjob.js:504-523: rows is filtered and captured at the start; then finContractSnap = finContractSnapOf(finContractRows) runs at the end. • 9219zk-finance-boq-phone.js:53-60 (finBqAddAt) and :75-80 (finBqClose).
A8: NS-H2 | B8: New screens review | C8: High | D8: Bill of Quantities on the phone (9219zk) | E8: Phone BoQ "Remove" does nothing: the confirm dialog opens behind the edit sheet | F8: Fixed (waiting for Push origin) | G8: Fixed | H8: Fixed on 24 Oct night (tested); live since you pressed Push origin. | I8: 24 Oct (night) | J8: commit 698ae60 | K8: • The sheet and the confirm overlay have the same z-index, so DOM order decides which is on top. • #confirmModalOverlay is created the first time any confirm is used in the session. #finBqOv is created the first time the BoQ sheet opens. • If any confirm has been shown earlier in the session (very common), the confirm sits earlier in the DOM and is painted under the sheet. | L8: • 9219zk-finance-boq-phone.js:120-125 (finBqDelete asks customConfirm while the sheet is still open). • 9219zk-finance-boq-phone.js:158 (.bq-ov{z-index:10050}). • 9219m-yard-stock.js:280 (#confirmModalOverlay{z-index:10050 !important}). • 110-routing.js:191-197 (the confirm overlay is created once and appended to body).
A9: FIN-NEW-01 | B9: Finance re-check | C9: Medium | D9: Subcontracts / CIS / Xero (side effect of the FA-06 fix) | E9: Subcontractor bills posted to Xero now include the contra charge, so Xero shows the contra as still owed | F9: Andy to decide | G9: Fixed | H9: The CIS record stores the contra, and Xero v10 adds it as a minus line on the bill. | I9: 25 Oct | J9: finance-done: 912:297; xero v10 deployed 25 Oct | K9: Since the FA-06 fix, fin_sub_payments stores labour and gross before the contra charge. This is correct for CIS. But the Xero bill is built from labour + materials, so it now includes the contra. The payment actually made (net_pay) is after the contra, and nothing posts the contra to Xero as a credit or negative line. | L9: 912-finance-subcontracts.js:279-283 (gross = net_due + contraNow, labour = gross − materials stored on fin_sub_payments). Deployed xero function v9, push_sub_payment (the bill = labour line + materials line, NoTax). | M9: FX-P2
A10: FX-P1 | B10: Fix check review | C10: Medium | D10: Purchases › Inbox (FA-03) | E10: An inbox item can be left "filed" with no purchase invoice, and drop out of sight | F10: Open | G10: Fixed | H10: Stuck "filed" inbox invoices show again and can be filed; only one person can claim one at a time. (One server step would be stronger.) | I10: 25 Oct | J10: finance-done: 906:26, 9219b:120, 914, 9219l | K10: The claim sets status:'filed' before the purchase invoice is inserted. If the insert doesn't complete, the only recovery is a second dbUpdate(...{status:'new'}). That second call fails too when the cause was a dropped connection: dbInsert catches the network error and returns null, then the revert PATCH also fails. It also fails if the app is closed or backgrounded between the two calls. The row is then status='filed', purchase_invoice_id=null. The Purchases inbox only loads status=eq.new, and no screen lists filed items with no invoice. A failed claim (offline) also shows "This one has just been filed by someone else", which is wrong, alongside the generic "Update failed" toast. | L10: src/js/9219b-finance-purchases.js:96-103 (and 906-finance-inbox.js:188-193); list query at 9219b-finance-purchases.js:119 | M10: FIN-NEW-04 (toast part)
A11: FX-P2 | B11: Fix check review | C11: Medium | D11: Subcontracts / CIS → Xero (FA-06) | E11: Subcontract bill in Xero is now overstated by the contra charge | F11: Andy to decide | G11: Fixed | H11: Same as FIN-NEW-01: the contra goes to Xero as a minus line. | I11: 25 Oct | J11: finance-done: 912:297; xero v10 deployed 25 Oct | K11: The CIS figures are now right per CISR15030: gross before contra, and cis_deduction on that. But the same fin_sub_payments row feeds Xero, which posts a bill of labour + materials = net due + this time's contra. The subcontractor is actually paid pay_amount = net due − CIS. Nothing posts the contra to Xero, so Xero shows them owed the contra amount on top. Fix-C flags this, but it is still unfixed and the bill posts automatically like any other. | L11: src/js/912-finance-subcontracts.js:283-286 (CIS record labour/gross now before contra); supabase/functions/xero/index.ts:417-418 (push_sub_payment posts labour + materials) | M11: FIN-NEW-01
A12: NS-M1 | B12: New screens review | C12: Medium | D12: Contract value: typed vs BoQ (9219zi), used by all three BoQ save paths | E12: A failed read in finCvPatch overwrites a typed (manual) contract value with the BoQ total | F12: Fixed (waiting for Push origin) | G12: Fixed | H12: Fixed on 24 Oct night (tested); live since you pressed Push origin. | I12: 24 Oct (night) | J12: commit 698ae60 | K12: • finCvPatch reads job_finance.contract_value_source with dbSelect(...).catch(()=>[]). • dbSelect does not throw on failure: it returns [] (or a cached copy) on a network or server error (060-offline-read-cache.js:111-117). • An empty answer is treated as "not manual", so the patch includes contract_value: <BoQ total>, and the upsert that follows (in a separate request) overwrites the typed value. | L12: • 9219zi-finance-setup.js:12-15. • Called from 902-finance-applications.js:243 (Save button), 9219n-finance-newjob.js:522 (autosave) and 9219n-finance-newjob.js:739 (finAppAddLineCore). | M12: FIN-NEW-03
A13: NS-M2 | B13: New screens review | C13: Medium | D13: Project Overview (9219zj block, 9219q finVdRowHtml) | E13: The overview's "Variations & Day Works" row is cached for the whole session and never refreshes | F13: Fixed (waiting for Push origin) | G13: Fixed | H13: Fixed on 24 Oct night (tested); live since you pressed Push origin. | I13: 24 Oct (night) | J13: commit 698ae60 | K13: The totals are fetched the first time the row is drawn for a project. After that, every re-render reuses the cached lists. | L13: 9219q-finance-summary-cards.js:267-290. FIN_VD_DATA[siteId] is loaded once and never cleared; finVdLoad only runs when it is missing. | M13: Map L85
